Workbook

Sheet Inicio
I1: WhatsApp 302 337 9738 · asegurasig.2026@asegurasig.com
C2: Plan Anual de Trabajo SG-SST
C3: Formato gratuito con dashboard · ASEGURA SIG | I3: Su respaldo estratégico en Sistemas Integrados de Gestión
C6: 📌 ¿Qué exige la norma?
C7: • Decreto 1072 de 2015, art. 2.2.4.6.8, numeral 7: el empleador debe diseñar y desarrollar un plan de trabajo anual para alcanzar los objetivos del SG-SST, que identifique metas, responsabilidades, recursos y cronograma de actividades.
C8: • Decreto 1072 de 2015, art. 2.2.4.6.12, numeral 5: el plan debe estar firmado por el empleador y por el responsable del SG-SST.
C9: • Resolución 0312 de 2019: el plan anual de trabajo es estándar mínimo para empresas de 10 o menos, de 11 a 50 y de más de 50 trabajadores.
C11: 🗂️ Hojas de este libro
C12: 1. Datos → información de la empresa, mes de corte y rangos del semáforo (celdas amarillas).
C13: 2. Plan → actividades con listas desplegables (PHVA, componente 0312, programa, recursos, frecuencia) y cronograma P/E/N.
C14: 3. Dashboard → indicadores, semáforos y gráficos que se actualizan solos; filtre por programa con la lista desplegable.
C15: 4. Listas → catálogos que alimentan las listas desplegables (puede agregar programas o responsables).
C16: 5. Firmas → aprobación por el empleador y el responsable del SG-SST.
C18: 🧭 Paso a paso
C19: 1. Diligencie la hoja Datos. El "mes de corte" define hasta qué mes se mide el avance (por ejemplo, 6 = a junio).
... C38: ¿Quiere que le ayudemos a construir su plan 2027? WhatsApp 302 337 9738 · asegurasig.2026@asegurasig.com

Sheet Datos
D1: WhatsApp 302 337 9738 · asegurasig.2026@asegurasig.com
C2: Datos de la empresa
C3: Diligencie las celdas amarillas | D3: Su respaldo estratégico en Sistemas Integrados de Gestión
B6: Razón social | C6: Empresa Ejemplo S.A.S. (caso hipotético)
B7: NIT | C7: 900.000.000-0
B8: Actividad económica | C8: Metalmecánica (ejemplo)
B9: Clase de riesgo (I a V) | C9: III | D9: Lista desplegable
B10: Número de trabajadores | C10: 45
B11: Responsable del SG-SST
B12: Representante legal / empleador
B13: Año del plan | C13: 2027 | D13: Aparece en el título del plan y del dashboard.
B14: Mes de corte del seguimiento (1 a 12) | C14: 6 | D14: El avance se mide hasta este mes. Ejemplo: 6 = a junio.
B15: Meta de cumplimiento del plan | C15: 0.9 | D15: Definida por la empresa. 90 % es solo un ejemplo.
B16: 🟢 Óptimo desde | C16: 0.9 | D16: Rango del semáforo verde.
B17: 🟡 Aceptable desde | C17: 0.7 | D17: Rango del semáforo amarillo. Por debajo: 🔴 crítico.

Sheet Plan
AD1: WhatsApp 302 337 9738 · asegurasig.2026@asegurasig.com
D2: Plan Anual de Trabajo SG-SST
D3: Decreto 1072 de 2015 (art. 2.2.4.6.8 num. 7) · Resolución 0312 de 2019 | AD3: Su respaldo estratégico en Sistemas Integrados de Gestión
D4: =CONCATENATE("Año ",Datos!$C$13," · ",Datos!$C$6," · Corte: mes ",Datos!$C$14) -> Año 2027 · Empresa Ejemplo S.A.S. (caso hipotético) · Corte: mes 6
A5: ¿QUÉ SE VA A HACER? | L5: CRONOGRAMA · P = programada · E = ejecutada · N = no ejecutada | X5: SEGUIMIENTO AUTOMÁTICO
A6: N° | B6: Ciclo PHVA | C6: Componente Res. 0312 | D6: Programa | E6: Actividad | F6: Meta | G6: Responsable | H6: Recursos | I6: Presupuesto ($) | J6: Frecuencia | K6: Evidencia / entregable | L6: Ene | M6: Feb | N6: Mar | O6: Abr | P6: May | Q6: Jun | R6: Jul | S6: Ago | T6: Sep | U6: Oct | V6: Nov | W6: Dic | X6: Prog. año | Y6: Prog. a la fecha | Z6: Ejec. a la fecha | AA6: % a la fecha | AB6: Semáforo | AC6: Estado | AD6: Observaciones
A7: 1 | B7: P | C7: Gestión integral del SG-SST | D7: Gestión del sistema | E7: Revisar, firmar y divulgar la política de SST | F7: Política firmada y divulgada al 100 % del personal | G7: Gerencia | H7: Humanos | I7: 0 | J7: Anual | K7: Política firmada y acta de divulgación | L7: E | X7: =COUNTIF($L7:$W7,"P")+COUNTIF($L7:$W7,"E")+COUNTIF($L7:$W7,"N") -> 1 | Y7: =SUMPRODUCT((COLUMN($L7:$W7)-COLUMN($L7)+1<=Datos!$C$14)*(($L7:$W7="P")+($L7:$W7="E")+($L7:$W7="N"))) -> 1 | Z7: =SUMPRODUCT((COLUMN($L7:$W7)-COLUMN($L7)+1<=Datos!$C$14)*($L7:$W7="E")) -> 1 | AA7: =IF(Y7=0,"",Z7/Y7) -> 1 | AB7: =IF(Y7=0,"",IF(AA7>=Datos!$C$16,"🟢 Óptimo",IF(AA7>=Datos!$C$17,"🟡 Aceptable","🔴 Crítico"))) -> 🟢 Óptimo | AC7: =IF(X7=0,"",IF(COUNTIF($L7:$W7,"E")=X7,"✅ Cumplida",IF(Y7=0,"⏳ Por iniciar",IF(Z7<Y7,"⚠️ Atrasada","▶️ Al día")))) -> ✅ Cumplida
A8: 2 | B8: P | C8: Gestión integral del SG-SST | D8: Gestión del sistema | E8: Realizar la autoevaluación de estándares mínimos | F8: Autoevaluación con calificación | G8: Responsable SG-SST | H8: Humanos | I8: 0 | J8: Anual | K8: Formato de autoevaluación | L8: E | X8: =COUNTIF($L8:$W8,"P")+COUNTIF($L8:$W8,"E")+COUNTIF($L8:$W8,"N") -> 1 | Y8: =SUMPRODUCT((COLUMN($L8:$W8)-COLUMN($L8)+1<=Datos!$C$14)*(($L8:$W8="P")+($L8:$W8="E")+($L8:$W8="N"))) -> 1 | Z8: =SUMPRODUCT((COLUMN($L8:$W8)-COLUMN($L8)+1<=Datos!$C$14)*($L8:$W8="E")) -> 1 | AA8: =IF(Y8=0,"",Z8/Y8) -> 1 | AB8: =IF(Y8=0,"",IF(AA8>=Datos!$C$16,"🟢 Óptimo",IF(AA8>=Datos!$C$17,"🟡 Aceptable","🔴 Crítico"))) -> 🟢 Óptimo | AC8: =IF(X8=0,"",IF(COUNTIF($L8:$W8,"E")=X8,"✅ Cumplida",IF(Y8=0,"⏳ Por iniciar",IF(Z8<Y8,"⚠️ Atrasada","▶️ Al día")))) -> ✅ Cumplida
A9: 3 | B9: A | C9: Mejoramiento | D9: Gestión del sistema | E9: Elaborar el plan de mejoramiento según la autoevaluación | F9: Plan aprobado por la gerencia | G9: Responsable SG-SST | H9: Humanos | I9: 0 | J9: Anual | K9: Plan de mejoramiento | M9: E | X9: =COUNTIF($L9:$W9,"P")+COUNTIF($L9:$W9,"E")+COUNTIF($L9:$W9,"N") -> 1 | Y9: =SUMPRODUCT((COLUMN($L9:$W9)-COLUMN($L9)+1<=Datos!$C$14)*(($L9:$W9="P")+($L9:$W9="E")+($L9:$W9="N"))) -> 1 | Z9: =SUMPRODUCT((COLUMN($L9:$W9)-COLUMN($L9)+1<=Datos!$C$14)*($L9:$W9="E")) -> 1 | AA9: =IF(Y9=0,"",Z9/Y9) -> 1 | AB9: =IF(Y9=0,"",IF(AA9>=Datos!$C$16,"🟢 Óptimo",IF(AA9>=Datos!$C$17,"🟡 Aceptable","🔴 Crítico"))) -> 🟢 Óptimo | AC9: =IF(X9=0,"",IF(COUNTIF($L9:$W9,"E")=X9,"✅ Cumplida",IF(Y9=0,"⏳ Por iniciar",IF(Z9<Y9,"⚠️ Atrasada","▶️ Al día")))) -> ✅ Cumplida
A10: 4 | B10: P | C10: Gestión integral del SG-SST | D10: Gestión del sistema | E10: Reportar autoevaluación y plan de mejora en la plataforma del Ministerio del Trabajo | F10: Reporte dentro del plazo | G10: Responsable SG-SST | H10: Tecnológicos | I10: 0 | J10: Anual | K10: Constancia de reporte | N10: E | X10: =COUNTIF($L10:$W10,"P")+COUNTIF($L10:$W10,"E")+COUNTIF($L10:$W10,"N") -> 1 | Y10: =SUMPRODUCT((COLUMN($L10:$W10)-COLUMN($L10)+1<=Datos!$C$14)*(($L10:$W10="P")+($L10:$W10="E")+($L10:$W10="N"))) -> 1 | Z10: =SUMPRODUCT((COLUMN($L10:$W10)-COLUMN($L10)+1<=Datos!$C$14)*($L10:$W10="E")) -> 1 | AA10: =IF(Y10=0,"",Z10/Y10) -> 1 | AB10: =IF(Y10=0,"",IF(AA10>=Datos!$C$16,"🟢 Óptimo",IF(AA10>=Datos!$C$17,"🟡 Aceptable","🔴 Crítico"))) -> 🟢 Óptimo | AC10: =IF(X10=0,"",IF(COUNTIF($L10:$W10,"E")=X10,"✅ Cumplida",IF(Y10=0,"⏳ Por iniciar",IF(Z10<Y10,"⚠️ Atrasada","▶️ Al día")))) -> ✅ Cumplida
A11: 5 | B11: P | C11: Recursos | D11: Gestión del sistema | E11: Asignar y documentar el presupuesto del SG-SST | F11: Presupuesto aprobado | G11: Gerencia | H11: Financieros | I11: 0 | J11: Anual | K11: Presupuesto firmado | L11: E | X11: =COUNTIF($L11:$W11,"P")+COUNTIF($L11:$W11,"E")+COUNTIF($L11:$W11,"N") -> 1 | Y11: =SUMPRODUCT((COLUMN($L11:$W11)-COLUMN($L11)+1<=Datos!$C$14)*(($L11:$W11="P")+($L11:$W11="E")+($L11:$W11="N"))) -> 1 | Z11: =SUMPRODUCT((COLUMN($L11:$W11)-COLUMN($L11)+1<=Datos!$C$14)*($L11:$W11="E")) -> 1 | AA11: =IF(Y11=0,"",Z11/Y11) -> 1 | AB11: =IF(Y11=0,"",IF(AA11>=Datos!$C$16,"🟢 Óptimo",IF(AA11>=Datos!$C$17,"🟡 Aceptable","🔴 Crítico"))) -> 🟢 Óptimo | AC11: =IF(X11=0,"",IF(COUNTIF($L11:$W11,"E")=X11,"✅ Cumplida",IF(Y11=0,"⏳ Por iniciar",IF(Z11<Y11,"⚠️ Atrasada","▶️ Al día")))) -> ✅ Cumplida
A12: 6 | B12: P | C12: Gestión de peligros y riesgos | D12: Identificación de peligros | E12: Actualizar la matriz de peligros (GTC 45) con participación de los trabajadores | F12: 100 % de procesos evaluados | G12: Responsable SG-SST | H12: Humanos | I12: 0 | J12: Anual | K12: Matriz actualizada | M12: E | X12: =COUNTIF($L12:$W12,"P")+COUNTIF($L12:$W12,"E")+COUNTIF($L12:$W12,"N") -> 1 | Y12: =SUMPRODUCT((COLUMN($L12:$W12)-COLUMN($L12)+1<=Datos!$C$14)*(($L12:$W12="P")+($L12:$W12="E")+($L12:$W12="N"))) -> 1 | Z12: =SUMPRODUCT((COLUMN($L12:$W12)-COLUMN($L12)+1<=Datos!$C$14)*($L12:$W12="E")) -> 1 | AA12: =IF(Y12=0,"",Z12/Y12) -> 1 | AB12: =IF(Y12=0,"",IF(AA12>=Datos!$C$16,"🟢 Óptimo",IF(AA12>=Datos!$C$17,"🟡 Aceptable","🔴 Crítico"))) -> 🟢 Óptimo | AC12: =IF(X12=0,"",IF(COUNTIF($L12:$W12,"E")=X12,"✅ Cumplida",IF(Y12=0,"⏳ Por iniciar",IF(Z12<Y12,"⚠️ Atrasada","▶️ Al día")))) -> ✅ Cumplida
A13: 7 | B13: P | C13: Gestión integral del SG-SST | D13: Requisitos legales | E13: Actualizar y evaluar la matriz legal | F13: Matriz al día y evaluada | G13: Responsable SG-SST | H13: Humanos | I13: 0 | J13: Semestral | K13: Matriz legal | L13: E | R13: P | X13: =COUNTIF($L13:$W13,"P")+COUNTIF($L13:$W13,"E")+COUNTIF($L13:$W13,"N") -> 2 | Y13: =SUMPRODUCT((COLUMN($L13:$W13)-COLUMN($L13)+1<=Datos!$C$14)*(($L13:$W13="P")+($L13:$W13="E")+($L13:$W13="N"))) -> 1 | Z13: =SUMPRODUCT((COLUMN($L13:$W13)-COLUMN($L13)+1<=Datos!$C$14)*($L13:$W13="E")) -> 1 | AA13: =IF(Y13=0,"",Z13/Y13) -> 1 | AB13: =IF(Y13=0,"",IF(AA13>=Datos!$C$16,"🟢 Óptimo",IF(AA13>=Datos!$C$17,"🟡 Aceptable","🔴 Crítico"))) -> 🟢 Óptimo | AC13: =IF(X13=0,"",IF(COUNTIF($L13:$W13,"E")=X13,"✅ Cumplida",IF(Y13=0,"⏳ Por iniciar",IF(Z13<Y13,"⚠️ Atrasada","▶️ Al día")))) -> ▶️ Al día
A14: 8 | B14: P | C14: Gestión integral del SG-SST | D14: Gestión del sistema | E14: Definir objetivos, metas e indicadores del SG-SST | F14: Objetivos medibles con ficha | G14: Gerencia y responsable SG-SST | H14: Humanos | I14: 0 | J14: Anual | K14: Fichas de indicadores | L14: E | X14: =COUNTIF($L14:$W14,"P")+COUNTIF($L14:$W14,"E")+COUNTIF($L14:$W14,"N") -> 1 | Y14: =SUMPRODUCT((COLUMN($L14:$W14)-COLUMN($L14)+1<=Datos!$C$14)*(($L14:$W14="P")+($L14:$W14="E")+($L14:$W14="N"))) -> 1 | Z14: =SUMPRODUCT((COLUMN($L14:$W14)-COLUMN($L14)+1<=Datos!$C$14)*($L14:$W14="E")) -> 1 | AA14: =IF(Y14=0,"",Z14/Y14) -> 1 | AB14: =IF(Y14=0,"",IF(AA14>=Datos!$C$16,"🟢 Óptimo",IF(AA14>=Datos!$C$17,"🟡 Aceptable","🔴 Crítico"))) -> 🟢 Óptimo | AC14: =IF(X14=0,"",IF(COUNTIF($L14:$W14,"E")=X14,"✅ Cumplida",IF(Y14=0,"⏳ Por iniciar",IF(Z14<Y14,"⚠️ Atrasada","▶️ Al día")))) -> ✅ Cumplida
A15: 9 | B15: H | C15: Recursos | D15: Capacitación | E15: Inducción y reinducción en SST | F15: 100 % del personal nuevo y antiguo | G15: Talento humano | H15: Humanos | I15: 1500000 | J15: Semestral | K15: Registros de asistencia y evaluación | M15: E | S15: P | X15: =COUNTIF($L15:$W15,"P")+COUNTIF($L15:$W15,"E")+COUNTIF($L15:$W15,"N") -> 2 | Y15: =SUMPRODUCT((COLUMN($L15:$W15)-COLUMN($L15)+1<=Datos!$C$14)*(($L15:$W15="P")+($L15:$W15="E")+($L15:$W15="N"))) -> 1 | Z15: =SUMPRODUCT((COLUMN($L15:$W15)-COLUMN($L15)+1<=Datos!$C$14)*($L15:$W15="E")) -> 1 | AA15: =IF(Y15=0,"",Z15/Y15) -> 1 | AB15: =IF(Y15=0,"",IF(AA15>=Datos!$C$16,"🟢 Óptimo",IF(AA15>=Datos!$C$17,"🟡 Aceptable","🔴 Crítico"))) -> 🟢 Óptimo | AC15: =IF(X15=0,"",IF(COUNTIF($L15:$W15,"E")=X15,"✅ Cumplida",IF(Y15=0,"⏳ Por iniciar",IF(Z15<Y15,"⚠️ Atrasada","▶️ Al día")))) -> ▶️ Al día
A16: 10 | B16: H | C16: Recursos | D16: Capacitación | E16: Ejecutar el plan anual de capacitación por riesgos | F16: Capacitaciones del plan realizadas | G16: Responsable SG-SST | H16: Humanos y financieros | I16: 3000000 | J16: Bimestral | K16: Actas, asistencia y evaluaciones | N16: E | P16: N | R16: P | T16: P | V16: P | X16: =COUNTIF($L16:$W16,"P")+COUNTIF($L16:$W16,"E")+COUNTIF($L16:$W16,"N") -> 5 | Y16: =SUMPRODUCT((COLUMN($L16:$W16)-COLUMN($L16)+1<=Datos!$C$14)*(($L16:$W16="P")+($L16:$W16="E")+($L16:$W16="N"))) -> 2 | Z16: =SUMPRODUCT((COLUMN($L16:$W16)-COLUMN($L16)+1<=Datos!$C$14)*($L16:$W16="E")) -> 1 | AA16: =IF(Y16=0,"",Z16/Y16) -> 0.5 | AB16: =IF(Y16=0,"",IF(AA16>=Datos!$C$16,"🟢 Óptimo",IF(AA16>=Datos!$C$17,"🟡 Aceptable","🔴 Crítico"))) -> 🔴 Crítico | AC16: =IF(X16=0,"",IF(COUNTIF($L16:$W16,"E")=X16,"✅ Cumplida",IF(Y16=0,"⏳ Por iniciar",IF(Z16<Y16,"⚠️ Atrasada","▶️ Al día")))) -> ⚠️ Atrasada
A17: 11 | B17: H | C17: Recursos | D17: Comités | E17: Reuniones mensuales del COPASST o vigía | F17: 12 reuniones con acta | G17: Presidente COPASST | H17: Humanos | I17: 0 | J17: Mensual | K17: Actas de reunión | L17: E | M17: E | N17: E | O17: N | P17: E | Q17: E | R17: P | S17: P | T17: P | U17: P | V17: P | W17: P | X17: =COUNTIF($L17:$W17,"P")+COUNTIF($L17:$W17,"E")+COUNTIF($L17:$W17,"N") -> 12 | Y17: =SUMPRODUCT((COLUMN($L17:$W17)-COLUMN($L17)+1<=Datos!$C$14)*(($L17:$W17="P")+($L17:$W17="E")+($L17:$W17="N"))) -> 6 | Z17: =SUMPRODUCT((COLUMN($L17:$W17)-COLUMN($L17)+1<=Datos!$C$14)*($L17:$W17="E")) -> 5 | AA17: =IF(Y17=0,"",Z17/Y17) -> 0.83333333 | AB17: =IF(Y17=0,"",IF(AA17>=Datos!$C$16,"🟢 Óptimo",IF(AA17>=Datos!$C$17,"🟡 Aceptable","🔴 Crítico"))) -> 🟡 Aceptable | AC17: =IF(X17=0,"",IF(COUNTIF($L17:$W17,"E")=X17,"✅ Cumplida",IF(Y17=0,"⏳ Por iniciar",IF(Z17<Y17,"⚠️ Atrasada","▶️ Al día")))) -> ⚠️ Atrasada
A18: 12 | B18: H | C18: Recursos | D18: Comités | E18: Reuniones del Comité de Convivencia Laboral | F18: 4 reuniones con acta | G18: Comité de Convivencia | H18: Humanos | I18: 0 | J18: Trimestral | K18: Actas de reunión | N18: E | Q18: E | T18: P | W18: P | X18: =COUNTIF($L18:$W18,"P")+COUNTIF($L18:$W18,"E")+COUNTIF($L18:$W18,"N") -> 4 | Y18: =SUMPRODUCT((COLUMN($L18:$W18)-COLUMN($L18)+1<=Datos!$C$14)*(($L18:$W18="P")+($L18:$W18="E")+($L18:$W18="N"))) -> 2 | Z18: =SUMPRODUCT((COLUMN($L18:$W18)-COLUMN($L18)+1<=Datos!$C$14)*($L18:$W18="E")) -> 2 | AA18: =IF(Y18=0,"",Z18/Y18) -> 1 | AB18: =IF(Y18=0,"",IF(AA18>=Datos!$C$16,"🟢 Óptimo",IF(AA18>=Datos!$C$17,"🟡 Aceptable","🔴 Crítico"))) -> 🟢 Óptimo | AC18: =IF(X18=0,"",IF(COUNTIF($L18:$W18,"E")=X18,"✅ Cumplida",IF(Y18=0,"⏳ Por iniciar",IF(Z18<Y18,"⚠️ Atrasada","▶️ Al día")))) -> ▶️ Al día
A19: 13 | B19: H | C19: Gestión de la salud | D19: Medicina del trabajo | E19: Exámenes médicos ocupacionales periódicos según el profesiograma | F19: Personal programado evaluado | G19: Talento humano | H19: Financieros | I19: 6000000 | J19: Anual | K19: Certificados de aptitud | O19: E | P19: E | X19: =COUNTIF($L19:$W19,"P")+COUNTIF($L19:$W19,"E")+COUNTIF($L19:$W19,"N") -> 2 | Y19: =SUMPRODUCT((COLUMN($L19:$W19)-COLUMN($L19)+1<=Datos!$C$14)*(($L19:$W19="P")+($L19:$W19="E")+($L19:$W19="N"))) -> 2 | Z19: =SUMPRODUCT((COLUMN($L19:$W19)-COLUMN($L19)+1<=Datos!$C$14)*($L19:$W19="E")) -> 2 | AA19: =IF(Y19=0,"",Z19/Y19) -> 1 | AB19: =IF(Y19=0,"",IF(AA19>=Datos!$C$16,"🟢 Óptimo",IF(AA19>=Datos!$C$17,"🟡 Aceptable","🔴 Crítico"))) -> 🟢 Óptimo | AC19: =IF(X19=0,"",IF(COUNTIF($L19:$W19,"E")=X19,"✅ Cumplida",IF(Y19=0,"⏳ Por iniciar",IF(Z19<Y19,"⚠️ Atrasada","▶️ Al día")))) -> ✅ Cumplida
A20: 14 | B20: H | C20: Gestión de la salud | D20: Medicina del trabajo | E20: Analizar el diagnóstico de condiciones de salud | F20: Informe analizado con plan de acción | G20: Responsable SG-SST | H20: Humanos | I20: 0 | J20: Anual | K20: Informe y plan de acción | Q20: E | X20: =COUNTIF($L20:$W20,"P")+COUNTIF($L20:$W20,"E")+COUNTIF($L20:$W20,"N") -> 1 | Y20: =SUMPRODUCT((COLUMN($L20:$W20)-COLUMN($L20)+1<=Datos!$C$14)*(($L20:$W20="P")+($L20:$W20="E")+($L20:$W20="N"))) -> 1 | Z20: =SUMPRODUCT((COLUMN($L20:$W20)-COLUMN($L20)+1<=Datos!$C$14)*($L20:$W20="E")) -> 1 | AA20: =IF(Y20=0,"",Z20/Y20) -> 1 | AB20: =IF(Y20=0,"",IF(AA20>=Datos!$C$16,"🟢 Óptimo",IF(AA20>=Datos!$C$17,"🟡 Aceptable","🔴 Crítico"))) -> 🟢 Óptimo | AC20: =IF(X20=0,"",IF(COUNTIF($L20:$W20,"E")=X20,"✅ Cumplida",IF(Y20=0,"⏳ Por iniciar",IF(Z20<Y20,"⚠️ Atrasada","▶️ Al día")))) -> ✅ Cumplida
A21: 15 | B21: H | C21: Gestión de la salud | D21: Vigilancia epidemiológica | E21: Programa de prevención de desórdenes musculoesqueléticos | F21: Programa ejecutado según cronograma | G21: Responsable SG-SST | H21: ARL | I21: 800000 | J21: Bimestral | K21: Registros del programa | M21: E | O21: E | Q21: N | S21: P | U21: P | W21: P | X21: =COUNTIF($L21:$W21,"P")+COUNTIF($L21:$W21,"E")+COUNTIF($L21:$W21,"N") -> 6 | Y21: =SUMPRODUCT((COLUMN($L21:$W21)-COLUMN($L21)+1<=Datos!$C$14)*(($L21:$W21="P")+($L21:$W21="E")+($L21:$W21="N"))) -> 3 | Z21: =SUMPRODUCT((COLUMN($L21:$W21)-COLUMN($L21)+1<=Datos!$C$14)*($L21:$W21="E")) -> 2 | AA21: =IF(Y21=0,"",Z21/Y21) -> 0.66666667 | AB21: =IF(Y21=0,"",IF(AA21>=Datos!$C$16,"🟢 Óptimo",IF(AA21>=Datos!$C$17,"🟡 Aceptable","🔴 Crítico"))) -> 🔴 Crítico | AC21: =IF(X21=0,"",IF(COUNTIF($L21:$W21,"E")=X21,"✅ Cumplida",IF(Y21=0,"⏳ Por iniciar",IF(Z21<Y21,"⚠️ Atrasada","▶️ Al día")))) -> ⚠️ Atrasada
A22: 16 | B22: H | C22: Gestión de peligros y riesgos | D22: Riesgo psicosocial | E22: Aplicar o hacer seguimiento a la batería de riesgo psicosocial | F22: Según periodicidad de su nivel de riesgo | G22: Psicólogo especialista | H22: Financieros | I22: 2500000 | J22: Anual | K22: Informe de batería | R22: P | X22: =COUNTIF($L22:$W22,"P")+COUNTIF($L22:$W22,"E")+COUNTIF($L22:$W22,"N") -> 1 | Y22: =SUMPRODUCT((COLUMN($L22:$W22)-COLUMN($L22)+1<=Datos!$C$14)*(($L22:$W22="P")+($L22:$W22="E")+($L22:$W22="N"))) -> 0 | Z22: =SUMPRODUCT((COLUMN($L22:$W22)-COLUMN($L22)+1<=Datos!$C$14)*($L22:$W22="E")) -> 0 | AA22: =IF(Y22=0,"",Z22/Y22) | AB22: =IF(Y22=0,"",IF(AA22>=Datos!$C$16,"🟢 Óptimo",IF(AA22>=Datos!$C$17,"🟡 Aceptable","🔴 Crítico"))) | AC22: =IF(X22=0,"",IF(COUNTIF($L22:$W22,"E")=X22,"✅ Cumplida",IF(Y22=0,"⏳ Por iniciar",IF(Z22<Y22,"⚠️ Atrasada","▶️ Al día")))) -> ⏳ Por iniciar
A23: 17 | B23: H | C23: Gestión de peligros y riesgos | D23: Inspecciones | E23: Inspecciones planeadas a instalaciones, máquinas y herramientas | F23: Inspecciones del cronograma con hallazgos cerrados | G23: Responsable SG-SST y COPASST | H23: Humanos | I23: 0 | J23: Bimestral | K23: Formatos de inspección | M23: E | O23: E | Q23: E | S23: P | U23: P | W23: P | X23: =COUNTIF($L23:$W23,"P")+COUNTIF($L23:$W23,"E")+COUNTIF($L23:$W23,"N") -> 6 | Y23: =SUMPRODUCT((COLUMN($L23:$W23)-COLUMN($L23)+1<=Datos!$C$14)*(($L23:$W23="P")+($L23:$W23="E")+($L23:$W23="N"))) -> 3 | Z23: =SUMPRODUCT((COLUMN($L23:$W23)-COLUMN($L23)+1<=Datos!$C$14)*($L23:$W23="E")) -> 3 | AA23: =IF(Y23=0,"",Z23/Y23) -> 1 | AB23: =IF(Y23=0,"",IF(AA23>=Datos!$C$16,"🟢 Óptimo",IF(AA23>=Datos!$C$17,"🟡 Aceptable","🔴 Crítico"))) -> 🟢 Óptimo | AC23: =IF(X23=0,"",IF(COUNTIF($L23:$W23,"E")=X23,"✅ Cumplida",IF(Y23=0,"⏳ Por iniciar",IF(Z23<Y23,"⚠️ Atrasada","▶️ Al día")))) -> ▶️ Al día
A24: 18 | B24: H | C24: Gestión de peligros y riesgos | D24: Elementos de protección personal | E24: Entrega, reposición e inspección de EPP | F24: Personal con EPP vigente | G24: Almacén y SST | H24: Financieros | I24: 4000000 | J24: Trimestral | K24: Formatos de entrega | L24: E | O24: E | R24: P | U24: P | X24: =COUNTIF($L24:$W24,"P")+COUNTIF($L24:$W24,"E")+COUNTIF($L24:$W24,"N") -> 4 | Y24: =SUMPRODUCT((COLUMN($L24:$W24)-COLUMN($L24)+1<=Datos!$C$14)*(($L24:$W24="P")+($L24:$W24="E")+($L24:$W24="N"))) -> 2 | Z24: =SUMPRODUCT((COLUMN($L24:$W24)-COLUMN($L24)+1<=Datos!$C$14)*($L24:$W24="E")) -> 2 | AA24: =IF(Y24=0,"",Z24/Y24) -> 1 | AB24: =IF(Y24=0,"",IF(AA24>=Datos!$C$16,"🟢 Óptimo",IF(AA24>=Datos!$C$17,"🟡 Aceptable","🔴 Crítico"))) -> 🟢 Óptimo | AC24: =IF(X24=0,"",IF(COUNTIF($L24:$W24,"E")=X24,"✅ Cumplida",IF(Y24=0,"⏳ Por iniciar",IF(Z24<Y24,"⚠️ Atrasada","▶️ Al día")))) -> ▶️ Al día
A25: 19 | B25: H | C25: Gestión de amenazas | D25: Emergencias | E25: Actualizar el plan de prevención, preparación y respuesta ante emergencias | F25: Plan actualizado y divulgado | G25: Responsable SG-SST | H25: Humanos | I25: 0 | J25: Anual | K25: Plan actualizado | M25: E | X25: =COUNTIF($L25:$W25,"P")+COUNTIF($L25:$W25,"E")+COUNTIF($L25:$W25,"N") -> 1 | Y25: =SUMPRODUCT((COLUMN($L25:$W25)-COLUMN($L25)+1<=Datos!$C$14)*(($L25:$W25="P")+($L25:$W25="E")+($L25:$W25="N"))) -> 1 | Z25: =SUMPRODUCT((COLUMN($L25:$W25)-COLUMN($L25)+1<=Datos!$C$14)*($L25:$W25="E")) -> 1 | AA25: =IF(Y25=0,"",Z25/Y25) -> 1 | AB25: =IF(Y25=0,"",IF(AA25>=Datos!$C$16,"🟢 Óptimo",IF(AA25>=Datos!$C$17,"🟡 Aceptable","🔴 Crítico"))) -> 🟢 Óptimo | AC25: =IF(X25=0,"",IF(COUNTIF($L25:$W25,"E")=X25,"✅ Cumplida",IF(Y25=0,"⏳ Por iniciar",IF(Z25<Y25,"⚠️ Atrasada","▶️ Al día")))) -> ✅ Cumplida
A26: 20 | B26: H | C26: Gestión de amenazas | D26: Emergencias | E26: Capacitar y entrenar a la brigada de emergencias | F26: Brigada entrenada | G26: Coordinador de brigada | H26: Humanos y financieros | I26: 1500000 | J26: Semestral | K26: Registros de entrenamiento | N26: E | S26: P | X26: =COUNTIF($L26:$W26,"P")+COUNTIF($L26:$W26,"E")+COUNTIF($L26:$W26,"N") -> 2 | Y26: =SUMPRODUCT((COLUMN($L26:$W26)-COLUMN($L26)+1<=Datos!$C$14)*(($L26:$W26="P")+($L26:$W26="E")+($L26:$W26="N"))) -> 1 | Z26: =SUMPRODUCT((COLUMN($L26:$W26)-COLUMN($L26)+1<=Datos!$C$14)*($L26:$W26="E")) -> 1 | AA26: =IF(Y26=0,"",Z26/Y26) -> 1 | AB26: =IF(Y26=0,"",IF(AA26>=Datos!$C$16,"🟢 Óptimo",IF(AA26>=Datos!$C$17,"🟡 Aceptable","🔴 Crítico"))) -> 🟢 Óptimo | AC26: =IF(X26=0,"",IF(COUNTIF($L26:$W26,"E")=X26,"✅ Cumplida",IF(Y26=0,"⏳ Por iniciar",IF(Z26<Y26,"⚠️ Atrasada","▶️ Al día")))) -> ▶️ Al día
A27: 21 | B27: H | C27: Gestión de amenazas | D27: Emergencias | E27: Simulacro con participación de todos los trabajadores | F27: Mínimo 1 al año | G27: Coordinador de brigada | H27: Humanos | I27: 0 | J27: Anual | K27: Informe de evaluación del simulacro | U27: P | X27: =COUNTIF($L27:$W27,"P")+COUNTIF($L27:$W27,"E")+COUNTIF($L27:$W27,"N") -> 1 | Y27: =SUMPRODUCT((COLUMN($L27:$W27)-COLUMN($L27)+1<=Datos!$C$14)*(($L27:$W27="P")+($L27:$W27="E")+($L27:$W27="N"))) -> 0 | Z27: =SUMPRODUCT((COLUMN($L27:$W27)-COLUMN($L27)+1<=Datos!$C$14)*($L27:$W27="E")) -> 0 | AA27: =IF(Y27=0,"",Z27/Y27) | AB27: =IF(Y27=0,"",IF(AA27>=Datos!$C$16,"🟢 Óptimo",IF(AA27>=Datos!$C$17,"🟡 Aceptable","🔴 Crítico"))) | AC27: =IF(X27=0,"",IF(COUNTIF($L27:$W27,"E")=X27,"✅ Cumplida",IF(Y27=0,"⏳ Por iniciar",IF(Z27<Y27,"⚠️ Atrasada","▶️ Al día")))) -> ⏳ Por iniciar
A28: 22 | B28: H | C28: Gestión de amenazas | D28: Emergencias | E28: Inspeccionar extintores, botiquines y equipos de emergencia | F28: Equipos operativos | G28: Brigada | H28: Técnicos | I28: 600000 | J28: Trimestral | K28: Listas de chequeo | L28: E | O28: E | R28: P | U28: P | X28: =COUNTIF($L28:$W28,"P")+COUNTIF($L28:$W28,"E")+COUNTIF($L28:$W28,"N") -> 4 | Y28: =SUMPRODUCT((COLUMN($L28:$W28)-COLUMN($L28)+1<=Datos!$C$14)*(($L28:$W28="P")+($L28:$W28="E")+($L28:$W28="N"))) -> 2 | Z28: =SUMPRODUCT((COLUMN($L28:$W28)-COLUMN($L28)+1<=Datos!$C$14)*($L28:$W28="E")) -> 2 | AA28: =IF(Y28=0,"",Z28/Y28) -> 1 | AB28: =IF(Y28=0,"",IF(AA28>=Datos!$C$16,"🟢 Óptimo",IF(AA28>=Datos!$C$17,"🟡 Aceptable","🔴 Crítico"))) -> 🟢 Óptimo | AC28: =IF(X28=0,"",IF(COUNTIF($L28:$W28,"E")=X28,"✅ Cumplida",IF(Y28=0,"⏳ Por iniciar",IF(Z28<Y28,"⚠️ Atrasada","▶️ Al día")))) -> ▶️ Al día
A29: 23 | B29: H | C29: Gestión de peligros y riesgos | D29: Tareas de alto riesgo | E29: Gestionar permisos de trabajo y certificaciones (alturas, espacios confinados, caliente) | F29: 100 % de tareas con permiso | G29: Coordinador de alturas | H29: Humanos y financieros | I29: 2000000 | J29: Mensual | K29: Permisos y certificados | L29: E | M29: E | N29: N | O29: E | P29: E | Q29: E | R29: P | S29: P | T29: P | U29: P | V29: P | W29: P | X29: =COUNTIF($L29:$W29,"P")+COUNTIF($L29:$W29,"E")+COUNTIF($L29:$W29,"N") -> 12 | Y29: =SUMPRODUCT((COLUMN($L29:$W29)-COLUMN($L29)+1<=Datos!$C$14)*(($L29:$W29="P")+($L29:$W29="E")+($L29:$W29="N"))) -> 6 | Z29: =SUMPRODUCT((COLUMN($L29:$W29)-COLUMN($L29)+1<=Datos!$C$14)*($L29:$W29="E")) -> 5 | AA29: =IF(Y29=0,"",Z29/Y29) -> 0.83333333 | AB29: =IF(Y29=0,"",IF(AA29>=Datos!$C$16,"🟢 Óptimo",IF(AA29>=Datos!$C$17,"🟡 Aceptable","🔴 Crítico"))) -> 🟡 Aceptable | AC29: =IF(X29=0,"",IF(COUNTIF($L29:$W29,"E")=X29,"✅ Cumplida",IF(Y29=0,"⏳ Por iniciar",IF(Z29<Y29,"⚠️ Atrasada","▶️ Al día")))) -> ⚠️ Atrasada
A30: 24 | B30: H | C30: Gestión integral del SG-SST | D30: Contratistas | E30: Verificar el SG-SST y la afiliación de contratistas | F30: Contratistas evaluados | G30: Compras y SST | H30: Humanos | I30: 0 | J30: Semestral | K30: Listas de verificación | N30: E | T30: P | X30: =COUNTIF($L30:$W30,"P")+COUNTIF($L30:$W30,"E")+COUNTIF($L30:$W30,"N") -> 2 | Y30: =SUMPRODUCT((COLUMN($L30:$W30)-COLUMN($L30)+1<=Datos!$C$14)*(($L30:$W30="P")+($L30:$W30="E")+($L30:$W30="N"))) -> 1 | Z30: =SUMPRODUCT((COLUMN($L30:$W30)-COLUMN($L30)+1<=Datos!$C$14)*($L30:$W30="E")) -> 1 | AA30: =IF(Y30=0,"",Z30/Y30) -> 1 | AB30: =IF(Y30=0,"",IF(AA30>=Datos!$C$16,"🟢 Óptimo",IF(AA30>=Datos!$C$17,"🟡 Aceptable","🔴 Crítico"))) -> 🟢 Óptimo | AC30: =IF(X30=0,"",IF(COUNTIF($L30:$W30,"E")=X30,"✅ Cumplida",IF(Y30=0,"⏳ Por iniciar",IF(Z30<Y30,"⚠️ Atrasada","▶️ Al día")))) -> ▶️ Al día
A31: 25 | B31: H | C31: Gestión integral del SG-SST | D31: Gestión del cambio | E31: Evaluar el impacto en SST de cambios internos y externos | F31: Cambios evaluados antes de implementarse | G31: Responsable SG-SST | H31: Humanos | I31: 0 | J31: Semestral | K31: Formatos de gestión del cambio | Q31: E | W31: P | X31: =COUNTIF($L31:$W31,"P")+COUNTIF($L31:$W31,"E")+COUNTIF($L31:$W31,"N") -> 2 | Y31: =SUMPRODUCT((COLUMN($L31:$W31)-COLUMN($L31)+1<=Datos!$C$14)*(($L31:$W31="P")+($L31:$W31="E")+($L31:$W31="N"))) -> 1 | Z31: =SUMPRODUCT((COLUMN($L31:$W31)-COLUMN($L31)+1<=Datos!$C$14)*($L31:$W31="E")) -> 1 | AA31: =IF(Y31=0,"",Z31/Y31) -> 1 | AB31: =IF(Y31=0,"",IF(AA31>=Datos!$C$16,"🟢 Óptimo",IF(AA31>=Datos!$C$17,"🟡 Aceptable","🔴 Crítico"))) -> 🟢 Óptimo | AC31: =IF(X31=0,"",IF(COUNTIF($L31:$W31,"E")=X31,"✅ Cumplida",IF(Y31=0,"⏳ Por iniciar",IF(Z31<Y31,"⚠️ Atrasada","▶️ Al día")))) -> ▶️ Al día
A32: 26 | B32: H | C32: Gestión de la salud | D32: Accidentalidad | E32: Reportar e investigar incidentes, accidentes y enfermedades laborales | F32: 100 % investigados en los plazos | G32: Equipo investigador | H32: Humanos | I32: 0 | J32: Mensual | K32: Informes de investigación | L32: E | M32: E | N32: E | O32: E | P32: E | Q32: E | R32: P | S32: P | T32: P | U32: P | V32: P | W32: P | X32: =COUNTIF($L32:$W32,"P")+COUNTIF($L32:$W32,"E")+COUNTIF($L32:$W32,"N") -> 12 | Y32: =SUMPRODUCT((COLUMN($L32:$W32)-COLUMN($L32)+1<=Datos!$C$14)*(($L32:$W32="P")+($L32:$W32="E")+($L32:$W32="N"))) -> 6 | Z32: =SUMPRODUCT((COLUMN($L32:$W32)-COLUMN($L32)+1<=Datos!$C$14)*($L32:$W32="E")) -> 6 | AA32: =IF(Y32=0,"",Z32/Y32) -> 1 | AB32: =IF(Y32=0,"",IF(AA32>=Datos!$C$16,"🟢 Óptimo",IF(AA32>=Datos!$C$17,"🟡 Aceptable","🔴 Crítico"))) -> 🟢 Óptimo | AC32: =IF(X32=0,"",IF(COUNTIF($L32:$W32,"E")=X32,"✅ Cumplida",IF(Y32=0,"⏳ Por iniciar",IF(Z32<Y32,"⚠️ Atrasada","▶️ Al día")))) -> ▶️ Al día
A33: 27 | B33: H | C33: Gestión de peligros y riesgos | D33: Seguridad vial | E33: Inspección preoperacional y mantenimiento de vehículos | F33: Vehículos inspeccionados | G33: Líder de seguridad vial | H33: Técnicos | I33: 1200000 | J33: Mensual | K33: Listas preoperacionales | L33: E | M33: N | N33: E | O33: E | P33: E | Q33: E | R33: P | S33: P | T33: P | U33: P | V33: P | W33: P | X33: =COUNTIF($L33:$W33,"P")+COUNTIF($L33:$W33,"E")+COUNTIF($L33:$W33,"N") -> 12 | Y33: =SUMPRODUCT((COLUMN($L33:$W33)-COLUMN($L33)+1<=Datos!$C$14)*(($L33:$W33="P")+($L33:$W33="E")+($L33:$W33="N"))) -> 6 | Z33: =SUMPRODUCT((COLUMN($L33:$W33)-COLUMN($L33)+1<=Datos!$C$14)*($L33:$W33="E")) -> 5 | AA33: =IF(Y33=0,"",Z33/Y33) -> 0.83333333 | AB33: =IF(Y33=0,"",IF(AA33>=Datos!$C$16,"🟢 Óptimo",IF(AA33>=Datos!$C$17,"🟡 Aceptable","🔴 Crítico"))) -> 🟡 Aceptable | AC33: =IF(X33=0,"",IF(COUNTIF($L33:$W33,"E")=X33,"✅ Cumplida",IF(Y33=0,"⏳ Por iniciar",IF(Z33<Y33,"⚠️ Atrasada","▶️ Al día")))) -> ⚠️ Atrasada
A34: 28 | B34: V | C34: Verificación del SG-SST | D34: Indicadores | E34: Medir y analizar los indicadores del SG-SST | F34: Indicadores al día con análisis | G34: Responsable SG-SST | H34: Humanos | I34: 0 | J34: Trimestral | K34: Tablero de indicadores | N34: E | Q34: E | T34: P | W34: P | X34: =COUNTIF($L34:$W34,"P")+COUNTIF($L34:$W34,"E")+COUNTIF($L34:$W34,"N") -> 4 | Y34: =SUMPRODUCT((COLUMN($L34:$W34)-COLUMN($L34)+1<=Datos!$C$14)*(($L34:$W34="P")+($L34:$W34="E")+($L34:$W34="N"))) -> 2 | Z34: =SUMPRODUCT((COLUMN($L34:$W34)-COLUMN($L34)+1<=Datos!$C$14)*($L34:$W34="E")) -> 2 | AA34: =IF(Y34=0,"",Z34/Y34) -> 1 | AB34: =IF(Y34=0,"",IF(AA34>=Datos!$C$16,"🟢 Óptimo",IF(AA34>=Datos!$C$17,"🟡 Aceptable","🔴 Crítico"))) -> 🟢 Óptimo | AC34: =IF(X34=0,"",IF(COUNTIF($L34:$W34,"E")=X34,"✅ Cumplida",IF(Y34=0,"⏳ Por iniciar",IF(Z34<Y34,"⚠️ Atrasada","▶️ Al día")))) -> ▶️ Al día
A35: 29 | B35: V | C35: Verificación del SG-SST | D35: Auditoría | E35: Auditoría interna del SG-SST con participación del COPASST | F35: 1 auditoría con informe | G35: Auditor interno | H35: Humanos y financieros | I35: 1000000 | J35: Anual | K35: Informe de auditoría | T35: P | X35: =COUNTIF($L35:$W35,"P")+COUNTIF($L35:$W35,"E")+COUNTIF($L35:$W35,"N") -> 1 | Y35: =SUMPRODUCT((COLUMN($L35:$W35)-COLUMN($L35)+1<=Datos!$C$14)*(($L35:$W35="P")+($L35:$W35="E")+($L35:$W35="N"))) -> 0 | Z35: =SUMPRODUCT((COLUMN($L35:$W35)-COLUMN($L35)+1<=Datos!$C$14)*($L35:$W35="E")) -> 0 | AA35: =IF(Y35=0,"",Z35/Y35) | AB35: =IF(Y35=0,"",IF(AA35>=Datos!$C$16,"🟢 Óptimo",IF(AA35>=Datos!$C$17,"🟡 Aceptable","🔴 Crítico"))) | AC35: =IF(X35=0,"",IF(COUNTIF($L35:$W35,"E")=X35,"✅ Cumplida",IF(Y35=0,"⏳ Por iniciar",IF(Z35<Y35,"⚠️ Atrasada","▶️ Al día")))) -> ⏳ Por iniciar
A36: 30 | B36: V | C36: Verificación del SG-SST | D36: Revisión por la dirección | E36: Revisión por la alta dirección | F36: 1 revisión con acta | G36: Gerencia | H36: Humanos | I36: 0 | J36: Anual | K36: Acta de revisión | V36: P | X36: =COUNTIF($L36:$W36,"P")+COUNTIF($L36:$W36,"E")+COUNTIF($L36:$W36,"N") -> 1 | Y36: =SUMPRODUCT((COLUMN($L36:$W36)-COLUMN($L36)+1<=Datos!$C$14)*(($L36:$W36="P")+($L36:$W36="E")+($L36:$W36="N"))) -> 0 | Z36: =SUMPRODUCT((COLUMN($L36:$W36)-COLUMN($L36)+1<=Datos!$C$14)*($L36:$W36="E")) -> 0 | AA36: =IF(Y36=0,"",Z36/Y36) | AB36: =IF(Y36=0,"",IF(AA36>=Datos!$C$16,"🟢 Óptimo",IF(AA36>=Datos!$C$17,"🟡 Aceptable","🔴 Crítico"))) | AC36: =IF(X36=0,"",IF(COUNTIF($L36:$W36,"E")=X36,"✅ Cumplida",IF(Y36=0,"⏳ Por iniciar",IF(Z36<Y36,"⚠️ Atrasada","▶️ Al día")))) -> ⏳ Por iniciar
A37: 31 | B37: A | C37: Mejoramiento | D37: Mejora continua | E37: Seguimiento a acciones preventivas, correctivas y de mejora | F37: Acciones cerradas y eficaces | G37: Responsable SG-SST | H37: Humanos | I37: 0 | J37: Trimestral | K37: Matriz de acciones | O37: E | S37: P | W37: P | X37: =COUNTIF($L37:$W37,"P")+COUNTIF($L37:$W37,"E")+COUNTIF($L37:$W37,"N") -> 3 | Y37: =SUMPRODUCT((COLUMN($L37:$W37)-COLUMN($L37)+1<=Datos!$C$14)*(($L37:$W37="P")+($L37:$W37="E")+($L37:$W37="N"))) -> 1 | Z37: =SUMPRODUCT((COLUMN($L37:$W37)-COLUMN($L37)+1<=Datos!$C$14)*($L37:$W37="E")) -> 1 | AA37: =IF(Y37=0,"",Z37/Y37) -> 1 | AB37: =IF(Y37=0,"",IF(AA37>=Datos!$C$16,"🟢 Óptimo",IF(AA37>=Datos!$C$17,"🟡 Aceptable","🔴 Crítico"))) -> 🟢 Óptimo | AC37: =IF(X37=0,"",IF(COUNTIF($L37:$W37,"E")=X37,"✅ Cumplida",IF(Y37=0,"⏳ Por iniciar",IF(Z37<Y37,"⚠️ Atrasada","▶️ Al día")))) -> ▶️ Al día
A38: 32 | B38: A | C38: Gestión integral del SG-SST | D38: Gestión del sistema | E38: Rendición de cuentas en SST | F38: Rendición realizada por todos los niveles | G38: Gerencia | H38: Humanos | I38: 0 | J38: Anual | K38: Acta o registro | W38: P | X38: =COUNTIF($L38:$W38,"P")+COUNTIF($L38:$W38,"E")+COUNTIF($L38:$W38,"N") -> 1 | Y38: =SUMPRODUCT((COLUMN($L38:$W38)-COLUMN($L38)+1<=Datos!$C$14)*(($L38:$W38="P")+($L38:$W38="E")+($L38:$W38="N"))) -> 0 | Z38: =SUMPRODUCT((COLUMN($L38:$W38)-COLUMN($L38)+1<=Datos!$C$14)*($L38:$W38="E")) -> 0 | AA38: =IF(Y38=0,"",Z38/Y38) | AB38: =IF(Y38=0,"",IF(AA38>=Datos!$C$16,"🟢 Óptimo",IF(AA38>=Datos!$C$17,"🟡 Aceptable","🔴 Crítico"))) | AC38: =IF(X38=0,"",IF(COUNTIF($L38:$W38,"E")=X38,"✅ Cumplida",IF(Y38=0,"⏳ Por iniciar",IF(Z38<Y38,"⚠️ Atrasada","▶️ Al día")))) -> ⏳ Por iniciar
A39: 33 | X39: =COUNTIF($L39:$W39,"P")+COUNTIF($L39:$W39,"E")+COUNTIF($L39:$W39,"N") -> 0 | Y39: =SUMPRODUCT((COLUMN($L39:$W39)-COLUMN($L39)+1<=Datos!$C$14)*(($L39:$W39="P")+($L39:$W39="E")+($L39:$W39="N"))) -> 0 | Z39: =SUMPRODUCT((COLUMN($L39:$W39)-COLUMN($L39)+1<=Datos!$C$14)*($L39:$W39="E")) -> 0 | AA39: =IF(Y39=0,"",Z39/Y39) | AB39: =IF(Y39=0,"",IF(AA39>=Datos!$C$16,"🟢 Óptimo",IF(AA39>=Datos!$C$17,"🟡 Aceptable","🔴 Crítico"))) | AC39: =IF(X39=0,"",IF(COUNTIF($L39:$W39,"E")=X39,"✅ Cumplida",IF(Y39=0,"⏳ Por iniciar",IF(Z39<Y39,"⚠️ Atrasada","▶️ Al día"))))
A40: 34 | X40: =COUNTIF($L40:$W40,"P")+COUNTIF($L40:$W40,"E")+COUNTIF($L40:$W40,"N") -> 0 | Y40: =SUMPRODUCT((COLUMN($L40:$W40)-COLUMN($L40)+1<=Datos!$C$14)*(($L40:$W40="P")+($L40:$W40="E")+($L40:$W40="N"))) -> 0 | Z40: =SUMPRODUCT((COLUMN($L40:$W40)-COLUMN($L40)+1<=Datos!$C$14)*($L40:$W40="E")) -> 0 | AA40: =IF(Y40=0,"",Z40/Y40) | AB40: =IF(Y40=0,"",IF(AA40>=Datos!$C$16,"🟢 Óptimo",IF(AA40>=Datos!$C$17,"🟡 Aceptable","🔴 Crítico"))) | AC40: =IF(X40=0,"",IF(COUNTIF($L40:$W40,"E")=X40,"✅ Cumplida",IF(Y40=0,"⏳ Por iniciar",IF(Z40<Y40,"⚠️ Atrasada","▶️ Al día"))))
...

Sheet Dashboard
L1: WhatsApp 302 337 9738 · asegurasig.2026@asegurasig.com
D2: Dashboard del plan de trabajo
D3: Se actualiza solo con la hoja Plan | L3: Su respaldo estratégico en Sistemas Integrados de Gestión
D4: =CONCATENATE("Año ",Datos!$C$13," · ",Datos!$C$6," · Corte: mes ",Datos!$C$14) -> Año 2027 · Empresa Ejemplo S.A.S. (caso hipotético) · Corte: mes 6
N5: 📊 Gráficos dinámicos: cambian solos cuando marca E en la hoja Plan o cambia el mes de corte en Datos.
B6: Actividades | D6: Prog. a la fecha | E6: Ejec. a la fecha | F6: % cumplimiento | H6: Semáforo | I6: Presupuesto total | K6: Meta
B8: =COUNTA(Plan!$E$7:$E$56) -> 32 | D8: =SUM(Plan!$Y$7:$Y$56) -> 57 | E8: =SUM(Plan!$Z$7:$Z$56) -> 52 | F8: =IF(D8=0,0,E8/D8) -> 0.9122807 | H8: =IF(D8=0,"",IF(F8>=Datos!$C$16,"🟢 Óptimo",IF(F8>=Datos!$C$17,"🟡 Aceptable","🔴 Crítico"))) -> 🟢 Óptimo | I8: =SUM(Plan!$I$7:$I$56) -> 24100000 | K8: =Datos!$C$15 -> 0.9
B10: 📅 Avance mensual | H10: 🔄 Por ciclo PHVA
B11: Mes | C11: Programadas | D11: Ejecutadas | E11: % mes | F11: Meta | G11: % acumulado | H11: Ciclo | I11: Prog. fecha | J11: Ejec. fecha | K11: % | L11: Semáforo
B12: Ene | C12: =COUNTIF(Plan!$L$7:$L$56,"P")+COUNTIF(Plan!$L$7:$L$56,"E")+COUNTIF(Plan!$L$7:$L$56,"N") -> 11 | D12: =COUNTIF(Plan!$L$7:$L$56,"E") -> 11 | E12: =IF(OR(C12=0,1>Datos!$C$14),"",D12/C12) -> 1 | F12: =Datos!$C$15 -> 0.9 | G12: =IF(1>Datos!$C$14,"",IF(SUM($C$12:C12)=0,"",SUM($D$12:D12)/SUM($C$12:C12))) -> 1 | H12: P · Planear | I12: =SUMIF(Plan!$B$7:$B$56,"P",Plan!$Y$7:$Y$56) -> 7 | J12: =SUMIF(Plan!$B$7:$B$56,"P",Plan!$Z$7:$Z$56) -> 7 | K12: =IF(I12=0,"",J12/I12) -> 1 | L12: =IF(I12=0,"",IF(K12>=Datos!$C$16,"🟢",IF(K12>=Datos!$C$17,"🟡","🔴"))) -> 🟢
B13: Feb | C13: =COUNTIF(Plan!$M$7:$M$56,"P")+COUNTIF(Plan!$M$7:$M$56,"E")+COUNTIF(Plan!$M$7:$M$56,"N") -> 10 | D13: =COUNTIF(Plan!$M$7:$M$56,"E") -> 9 | E13: =IF(OR(C13=0,2>Datos!$C$14),"",D13/C13) -> 0.9 | F13: =Datos!$C$15 -> 0.9 | G13: =IF(2>Datos!$C$14,"",IF(SUM($C$12:C13)=0,"",SUM($D$12:D13)/SUM($C$12:C13))) -> 0.95238095 | H13: H · Hacer | I13: =SUMIF(Plan!$B$7:$B$56,"H",Plan!$Y$7:$Y$56) -> 46 | J13: =SUMIF(Plan!$B$7:$B$56,"H",Plan!$Z$7:$Z$56) -> 41 | K13: =IF(I13=0,"",J13/I13) -> 0.89130435 | L13: =IF(I13=0,"",IF(K13>=Datos!$C$16,"🟢",IF(K13>=Datos!$C$17,"🟡","🔴"))) -> 🟡
B14: Mar | C14: =COUNTIF(Plan!$N$7:$N$56,"P")+COUNTIF(Plan!$N$7:$N$56,"E")+COUNTIF(Plan!$N$7:$N$56,"N") -> 10 | D14: =COUNTIF(Plan!$N$7:$N$56,"E") -> 9 | E14: =IF(OR(C14=0,3>Datos!$C$14),"",D14/C14) -> 0.9 | F14: =Datos!$C$15 -> 0.9 | G14: =IF(3>Datos!$C$14,"",IF(SUM($C$12:C14)=0,"",SUM($D$12:D14)/SUM($C$12:C14))) -> 0.93548387 | H14: V · Verificar | I14: =SUMIF(Plan!$B$7:$B$56,"V",Plan!$Y$7:$Y$56) -> 2 | J14: =SUMIF(Plan!$B$7:$B$56,"V",Plan!$Z$7:$Z$56) -> 2 | K14: =IF(I14=0,"",J14/I14) -> 1 | L14: =IF(I14=0,"",IF(K14>=Datos!$C$16,"🟢",IF(K14>=Datos!$C$17,"🟡","🔴"))) -> 🟢
B15: Abr | C15: =COUNTIF(Plan!$O$7:$O$56,"P")+COUNTIF(Plan!$O$7:$O$56,"E")+COUNTIF(Plan!$O$7:$O$56,"N") -> 10 | D15: =COUNTIF(Plan!$O$7:$O$56,"E") -> 9 | E15: =IF(OR(C15=0,4>Datos!$C$14),"",D15/C15) -> 0.9 | F15: =Datos!$C$15 -> 0.9 | G15: =IF(4>Datos!$C$14,"",IF(SUM($C$12:C15)=0,"",SUM($D$12:D15)/SUM($C$12:C15))) -> 0.92682927 | H15: A · Actuar | I15: =SUMIF(Plan!$B$7:$B$56,"A",Plan!$Y$7:$Y$56) -> 2 | J15: =SUMIF(Plan!$B$7:$B$56,"A",Plan!$Z$7:$Z$56) -> 2 | K15: =IF(I15=0,"",J15/I15) -> 1 | L15: =IF(I15=0,"",IF(K15>=Datos!$C$16,"🟢",IF(K15>=Datos!$C$17,"🟡","🔴"))) -> 🟢
B16: May | C16: =COUNTIF(Plan!$P$7:$P$56,"P")+COUNTIF(Plan!$P$7:$P$56,"E")+COUNTIF(Plan!$P$7:$P$56,"N") -> 6 | D16: =COUNTIF(Plan!$P$7:$P$56,"E") -> 5 | E16: =IF(OR(C16=0,5>Datos!$C$14),"",D16/C16) -> 0.83333333 | F16: =Datos!$C$15 -> 0.9 | G16: =IF(5>Datos!$C$14,"",IF(SUM($C$12:C16)=0,"",SUM($D$12:D16)/SUM($C$12:C16))) -> 0.91489362
B17: Jun | C17: =COUNTIF(Plan!$Q$7:$Q$56,"P")+COUNTIF(Plan!$Q$7:$Q$56,"E")+COUNTIF(Plan!$Q$7:$Q$56,"N") -> 10 | D17: =COUNTIF(Plan!$Q$7:$Q$56,"E") -> 9 | E17: =IF(OR(C17=0,6>Datos!$C$14),"",D17/C17) -> 0.9 | F17: =Datos!$C$15 -> 0.9 | G17: =IF(6>Datos!$C$14,"",IF(SUM($C$12:C17)=0,"",SUM($D$12:D17)/SUM($C$12:C17))) -> 0.9122807 | H17: 📘 Por componente Res. 0312
B18: Jul | C18: =COUNTIF(Plan!$R$7:$R$56,"P")+COUNTIF(Plan!$R$7:$R$56,"E")+COUNTIF(Plan!$R$7:$R$56,"N") -> 9 | D18: =COUNTIF(Plan!$R$7:$R$56,"E") -> 0 | E18: =IF(OR(C18=0,7>Datos!$C$14),"",D18/C18) | F18: =Datos!$C$15 -> 0.9 | G18: =IF(7>Datos!$C$14,"",IF(SUM($C$12:C18)=0,"",SUM($D$12:D18)/SUM($C$12:C18))) | H18: Componente | I18: Prog. fecha | J18: Ejec. fecha | K18: % | L18: Presupuesto
B19: Ago | C19: =COUNTIF(Plan!$S$7:$S$56,"P")+COUNTIF(Plan!$S$7:$S$56,"E")+COUNTIF(Plan!$S$7:$S$56,"N") -> 9 | D19: =COUNTIF(Plan!$S$7:$S$56,"E") -> 0 | E19: =IF(OR(C19=0,8>Datos!$C$14),"",D19/C19) | F19: =Datos!$C$15 -> 0.9 | G19: =IF(8>Datos!$C$14,"",IF(SUM($C$12:C19)=0,"",SUM($D$12:D19)/SUM($C$12:C19))) | H19: Recursos | I19: =SUMIF(Plan!$C$7:$C$56,H19,Plan!$Y$7:$Y$56) -> 12 | J19: =SUMIF(Plan!$C$7:$C$56,H19,Plan!$Z$7:$Z$56) -> 10 | K19: =IF(I19=0,"",J19/I19) -> 0.83333333 | L19: =SUMIF(Plan!$C$7:$C$56,H19,Plan!$I$7:$I$56) -> 4500000
B20: Sep | C20: =COUNTIF(Plan!$T$7:$T$56,"P")+COUNTIF(Plan!$T$7:$T$56,"E")+COUNTIF(Plan!$T$7:$T$56,"N") -> 9 | D20: =COUNTIF(Plan!$T$7:$T$56,"E") -> 0 | E20: =IF(OR(C20=0,9>Datos!$C$14),"",D20/C20) | F20: =Datos!$C$15 -> 0.9 | G20: =IF(9>Datos!$C$14,"",IF(SUM($C$12:C20)=0,"",SUM($D$12:D20)/SUM($C$12:C20))) | H20: Gestión integral del SG-SST | I20: =SUMIF(Plan!$C$7:$C$56,H20,Plan!$Y$7:$Y$56) -> 7 | J20: =SUMIF(Plan!$C$7:$C$56,H20,Plan!$Z$7:$Z$56) -> 7 | K20: =IF(I20=0,"",J20/I20) -> 1 | L20: =SUMIF(Plan!$C$7:$C$56,H20,Plan!$I$7:$I$56) -> 0
B21: Oct | C21: =COUNTIF(Plan!$U$7:$U$56,"P")+COUNTIF(Plan!$U$7:$U$56,"E")+COUNTIF(Plan!$U$7:$U$56,"N") -> 9 | D21: =COUNTIF(Plan!$U$7:$U$56,"E") -> 0 | E21: =IF(OR(C21=0,10>Datos!$C$14),"",D21/C21) | F21: =Datos!$C$15 -> 0.9 | G21: =IF(10>Datos!$C$14,"",IF(SUM($C$12:C21)=0,"",SUM($D$12:D21)/SUM($C$12:C21))) | H21: Gestión de la salud | I21: =SUMIF(Plan!$C$7:$C$56,H21,Plan!$Y$7:$Y$56) -> 12 | J21: =SUMIF(Plan!$C$7:$C$56,H21,Plan!$Z$7:$Z$56) -> 11 | K21: =IF(I21=0,"",J21/I21) -> 0.91666667 | L21: =SUMIF(Plan!$C$7:$C$56,H21,Plan!$I$7:$I$56) -> 6800000
B22: Nov | C22: =COUNTIF(Plan!$V$7:$V$56,"P")+COUNTIF(Plan!$V$7:$V$56,"E")+COUNTIF(Plan!$V$7:$V$56,"N") -> 6 | D22: =COUNTIF(Plan!$V$7:$V$56,"E") -> 0 | E22: =IF(OR(C22=0,11>Datos!$C$14),"",D22/C22) | F22: =Datos!$C$15 -> 0.9 | G22: =IF(11>Datos!$C$14,"",IF(SUM($C$12:C22)=0,"",SUM($D$12:D22)/SUM($C$12:C22))) | H22: Gestión de peligros y riesgos | I22: =SUMIF(Plan!$C$7:$C$56,H22,Plan!$Y$7:$Y$56) -> 18 | J22: =SUMIF(Plan!$C$7:$C$56,H22,Plan!$Z$7:$Z$56) -> 16 | K22: =IF(I22=0,"",J22/I22) -> 0.88888889 | L22: =SUMIF(Plan!$C$7:$C$56,H22,Plan!$I$7:$I$56) -> 9700000
B23: Dic | C23: =COUNTIF(Plan!$W$7:$W$56,"P")+COUNTIF(Plan!$W$7:$W$56,"E")+COUNTIF(Plan!$W$7:$W$56,"N") -> 11 | D23: =COUNTIF(Plan!$W$7:$W$56,"E") -> 0 | E23: =IF(OR(C23=0,12>Datos!$C$14),"",D23/C23) | F23: =Datos!$C$15 -> 0.9 | G23: =IF(12>Datos!$C$14,"",IF(SUM($C$12:C23)=0,"",SUM($D$12:D23)/SUM($C$12:C23))) | H23: Gestión de amenazas | I23: =SUMIF(Plan!$C$7:$C$56,H23,Plan!$Y$7:$Y$56) -> 4 | J23: =SUMIF(Plan!$C$7:$C$56,H23,Plan!$Z$7:$Z$56) -> 4 | K23: =IF(I23=0,"",J23/I23) -> 1 | L23: =SUMIF(Plan!$C$7:$C$56,H23,Plan!$I$7:$I$56) -> 2100000
H24: Verificación del SG-SST | I24: =SUMIF(Plan!$C$7:$C$56,H24,Plan!$Y$7:$Y$56) -> 2 | J24: =SUMIF(Plan!$C$7:$C$56,H24,Plan!$Z$7:$Z$56) -> 2 | K24: =IF(I24=0,"",J24/I24) -> 1 | L24: =SUMIF(Plan!$C$7:$C$56,H24,Plan!$I$7:$I$56) -> 1000000
H25: Mejoramiento | I25: =SUMIF(Plan!$C$7:$C$56,H25,Plan!$Y$7:$Y$56) -> 2 | J25: =SUMIF(Plan!$C$7:$C$56,H25,Plan!$Z$7:$Z$56) -> 2 | K25: =IF(I25=0,"",J25/I25) -> 1 | L25: =SUMIF(Plan!$C$7:$C$56,H25,Plan!$I$7:$I$56) -> 0
B26: 🧩 Por programa
B27: Programa | D27: Actividades | E27: Prog. fecha | F27: Ejec. fecha | G27: % | H27: Semáforo | I27: Presupuesto
B28: Gestión del sistema | D28: =COUNTIF(Plan!$D$7:$D$56,B28) -> 7 | E28: =SUMIF(Plan!$D$7:$D$56,B28,Plan!$Y$7:$Y$56) -> 6 | F28: =SUMIF(Plan!$D$7:$D$56,B28,Plan!$Z$7:$Z$56) -> 6 | G28: =IF(E28=0,"",F28/E28) -> 1 | H28: =IF(E28=0,"",IF(G28>=Datos!$C$16,"🟢 Óptimo",IF(G28>=Datos!$C$17,"🟡 Aceptable","🔴 Crítico"))) -> 🟢 Óptimo | I28: =SUMIF(Plan!$D$7:$D$56,B28,Plan!$I$7:$I$56) -> 0
B29: Requisitos legales | D29: =COUNTIF(Plan!$D$7:$D$56,B29) -> 1 | E29: =SUMIF(Plan!$D$7:$D$56,B29,Plan!$Y$7:$Y$56) -> 1 | F29: =SUMIF(Plan!$D$7:$D$56,B29,Plan!$Z$7:$Z$56) -> 1 | G29: =IF(E29=0,"",F29/E29) -> 1 | H29: =IF(E29=0,"",IF(G29>=Datos!$C$16,"🟢 Óptimo",IF(G29>=Datos!$C$17,"🟡 Aceptable","🔴 Crítico"))) -> 🟢 Óptimo | I29: =SUMIF(Plan!$D$7:$D$56,B29,Plan!$I$7:$I$56) -> 0
B30: Identificación de peligros | D30: =COUNTIF(Plan!$D$7:$D$56,B30) -> 1 | E30: =SUMIF(Plan!$D$7:$D$56,B30,Plan!$Y$7:$Y$56) -> 1 | F30: =SUMIF(Plan!$D$7:$D$56,B30,Plan!$Z$7:$Z$56) -> 1 | G30: =IF(E30=0,"",F30/E30) -> 1 | H30: =IF(E30=0,"",IF(G30>=Datos!$C$16,"🟢 Óptimo",IF(G30>=Datos!$C$17,"🟡 Aceptable","🔴 Crítico"))) -> 🟢 Óptimo | I30: =SUMIF(Plan!$D$7:$D$56,B30,Plan!$I$7:$I$56) -> 0
B31: Capacitación | D31: =COUNTIF(Plan!$D$7:$D$56,B31) -> 2 | E31: =SUMIF(Plan!$D$7:$D$56,B31,Plan!$Y$7:$Y$56) -> 3 | F31: =SUMIF(Plan!$D$7:$D$56,B31,Plan!$Z$7:$Z$56) -> 2 | G31: =IF(E31=0,"",F31/E31) -> 0.66666667 | H31: =IF(E31=0,"",IF(G31>=Datos!$C$16,"🟢 Óptimo",IF(G31>=Datos!$C$17,"🟡 Aceptable","🔴 Crítico"))) -> 🔴 Crítico | I31: =SUMIF(Plan!$D$7:$D$56,B31,Plan!$I$7:$I$56) -> 4500000
B32: Comités | D32: =COUNTIF(Plan!$D$7:$D$56,B32) -> 2 | E32: =SUMIF(Plan!$D$7:$D$56,B32,Plan!$Y$7:$Y$56) -> 8 | F32: =SUMIF(Plan!$D$7:$D$56,B32,Plan!$Z$7:$Z$56) -> 7 | G32: =IF(E32=0,"",F32/E32) -> 0.875 | H32: =IF(E32=0,"",IF(G32>=Datos!$C$16,"🟢 Óptimo",IF(G32>=Datos!$C$17,"🟡 Aceptable","🔴 Crítico"))) -> 🟡 Aceptable | I32: =SUMIF(Plan!$D$7:$D$56,B32,Plan!$I$7:$I$56) -> 0
B33: Medicina del trabajo | D33: =COUNTIF(Plan!$D$7:$D$56,B33) -> 2 | E33: =SUMIF(Plan!$D$7:$D$56,B33,Plan!$Y$7:$Y$56) -> 3 | F33: =SUMIF(Plan!$D$7:$D$56,B33,Plan!$Z$7:$Z$56) -> 3 | G33: =IF(E33=0,"",F33/E33) -> 1 | H33: =IF(E33=0,"",IF(G33>=Datos!$C$16,"🟢 Óptimo",IF(G33>=Datos!$C$17,"🟡 Aceptable","🔴 Crítico"))) -> 🟢 Óptimo | I33: =SUMIF(Plan!$D$7:$D$56,B33,Plan!$I$7:$I$56) -> 6000000
B34: Vigilancia epidemiológica | D34: =COUNTIF(Plan!$D$7:$D$56,B34) -> 1 | E34: =SUMIF(Plan!$D$7:$D$56,B34,Plan!$Y$7:$Y$56) -> 3 | F34: =SUMIF(Plan!$D$7:$D$56,B34,Plan!$Z$7:$Z$56) -> 2 | G34: =IF(E34=0,"",F34/E34) -> 0.66666667 | H34: =IF(E34=0,"",IF(G34>=Datos!$C$16,"🟢 Óptimo",IF(G34>=Datos!$C$17,"🟡 Aceptable","🔴 Crítico"))) -> 🔴 Crítico | I34: =SUMIF(Plan!$D$7:$D$56,B34,Plan!$I$7:$I$56) -> 800000
B35: Riesgo psicosocial | D35: =COUNTIF(Plan!$D$7:$D$56,B35) -> 1 | E35: =SUMIF(Plan!$D$7:$D$56,B35,Plan!$Y$7:$Y$56) -> 0 | F35: =SUMIF(Plan!$D$7:$D$56,B35,Plan!$Z$7:$Z$56) -> 0 | G35: =IF(E35=0,"",F35/E35) | H35: =IF(E35=0,"",IF(G35>=Datos!$C$16,"🟢 Óptimo",IF(G35>=Datos!$C$17,"🟡 Aceptable","🔴 Crítico"))) | I35: =SUMIF(Plan!$D$7:$D$56,B35,Plan!$I$7:$I$56) -> 2500000
B36: Inspecciones | D36: =COUNTIF(Plan!$D$7:$D$56,B36) -> 1 | E36: =SUMIF(Plan!$D$7:$D$56,B36,Plan!$Y$7:$Y$56) -> 3 | F36: =SUMIF(Plan!$D$7:$D$56,B36,Plan!$Z$7:$Z$56) -> 3 | G36: =IF(E36=0,"",F36/E36) -> 1 | H36: =IF(E36=0,"",IF(G36>=Datos!$C$16,"🟢 Óptimo",IF(G36>=Datos!$C$17,"🟡 Aceptable","🔴 Crítico"))) -> 🟢 Óptimo | I36: =SUMIF(Plan!$D$7:$D$56,B36,Plan!$I$7:$I$56) -> 0
B37: Elementos de protección personal | D37: =COUNTIF(Plan!$D$7:$D$56,B37) -> 1 | E37: =SUMIF(Plan!$D$7:$D$56,B37,Plan!$Y$7:$Y$56) -> 2 | F37: =SUMIF(Plan!$D$7:$D$56,B37,Plan!$Z$7:$Z$56) -> 2 | G37: =IF(E37=0,"",F37/E37) -> 1 | H37: =IF(E37=0,"",IF(G37>=Datos!$C$16,"🟢 Óptimo",IF(G37>=Datos!$C$17,"🟡 Aceptable","🔴 Crítico"))) -> 🟢 Óptimo | I37: =SUMIF(Plan!$D$7:$D$56,B37,Plan!$I$7:$I$56) -> 4000000
B38: Emergencias | D38: =COUNTIF(Plan!$D$7:$D$56,B38) -> 4 | E38: =SUMIF(Plan!$D$7:$D$56,B38,Plan!$Y$7:$Y$56) -> 4 | F38: =SUMIF(Plan!$D$7:$D$56,B38,Plan!$Z$7:$Z$56) -> 4 | G38: =IF(E38=0,"",F38/E38) -> 1 | H38: =IF(E38=0,"",IF(G38>=Datos!$C$16,"🟢 Óptimo",IF(G38>=Datos!$C$17,"🟡 Aceptable","🔴 Crítico"))) -> 🟢 Óptimo | I38: =SUMIF(Plan!$D$7:$D$56,B38,Plan!$I$7:$I$56) -> 2100000
B39: Tareas de alto riesgo | D39: =COUNTIF(Plan!$D$7:$D$56,B39) -> 1 | E39: =SUMIF(Plan!$D$7:$D$56,B39,Plan!$Y$7:$Y$56) -> 6 | F39: =SUMIF(Plan!$D$7:$D$56,B39,Plan!$Z$7:$Z$56) -> 5 | G39: =IF(E39=0,"",F39/E39) -> 0.83333333 | H39: =IF(E39=0,"",IF(G39>=Datos!$C$16,"🟢 Óptimo",IF(G39>=Datos!$C$17,"🟡 Aceptable","🔴 Crítico"))) -> 🟡 Aceptable | I39: =SUMIF(Plan!$D$7:$D$56,B39,Plan!$I$7:$I$56) -> 2000000
... B47: Seguridad vial | D47: =COUNTIF(Plan!$D$7:$D$56,B47) -> 1 | E47: =SUMIF(Plan!$D$7:$D$56,B47,Plan!$Y$7:$Y$56) -> 6 | F47: =SUMIF(Plan!$D$7:$D$56,B47,Plan!$Z$7:$Z$56) -> 5 | G47: =IF(E47=0,"",F47/E47) -> 0.83333333 | H47: =IF(E47=0,"",IF(G47>=Datos!$C$16,"🟢 Óptimo",IF(G47>=Datos!$C$17,"🟡 Aceptable","🔴 Crítico"))) -> 🟡 Aceptable | I47: =SUMIF(Plan!$D$7:$D$56,B47,Plan!$I$7:$I$56) -> 1200000
B50: 🔎 Consulte un programa
B51: Seleccione: | C51: Emergencias
...

Sheet Listas
F1: WhatsApp 302 337 9738 · asegurasig.2026@asegurasig.com
C2: Listas desplegables
C3: Puede agregar elementos al final de cada columna | F3: Su respaldo estratégico en Sistemas Integrados de Gestión
A6: Ciclo PHVA | B6: Componente Res. 0312 | C6: Programa | D6: Recursos | E6: Frecuencia | F6: Marca mensual
A7: P | B7: Recursos | C7: Gestión del sistema | D7: Humanos | E7: Única | F7: P
A8: H | B8: Gestión integral del SG-SST | C8: Requisitos legales | D8: Financieros | E8: Mensual | F8: E
A9: V | B9: Gestión de la salud | C9: Identificación de peligros | D9: Técnicos | E9: Bimestral | F9: N
A10: A | B10: Gestión de peligros y riesgos | C10: Capacitación | D10: Tecnológicos | E10: Trimestral
B11: Gestión de amenazas | C11: Comités | D11: Humanos y financieros | E11: Semestral
B12: Verificación del SG-SST | C12: Medicina del trabajo | D12: Humanos y técnicos | E12: Anual
B13: Mejoramiento | C13: Vigilancia epidemiológica | D13: ARL | E13: Cuando ocurra
C14: Riesgo psicosocial
C15: Inspecciones
C16: Elementos de protección personal
C17: Emergencias
C18: Tareas de alto riesgo
C19: Contratistas
C20: Gestión del cambio
C21: Accidentalidad
C22: Indicadores
C23: Auditoría
C24: Revisión por la dirección
C25: Mejora continua
C26: Seguridad vial
A31: P = Planear · H = Hacer · V = Verificar · A = Actuar | P = programada · E = ejecutada · N = no ejecutada

Sheet Firmas
F1: WhatsApp 302 337 9738 · asegurasig.2026@asegurasig.com
C2: Aprobación del plan
C3: Decreto 1072 de 2015, art. 2.2.4.6.12 num. 5 | F3: Su respaldo estratégico en Sistemas Integrados de Gestión
B6: Plan anual de trabajo del SG-SST · Año: | C6: =Datos!$C$13 -> 2027
B7: Empresa: | C7: =Datos!$C$6 -> Empresa Ejemplo S.A.S. (caso hipotético)
B8: Total de actividades: | C8: =COUNTA(Plan!$E$7:$E$56) -> 32
B9: Actividades programadas en el año: | C9: =SUM(Plan!$X$7:$X$56) -> 110
B10: Presupuesto total del plan: | C10: =SUM(Plan!$I$7:$I$56) -> 24100000
B16: _______________________________ | E16: _______________________________
B17: Empleador / representante legal | E17: Responsable del SG-SST
B18: =Datos!$C$12 -> 0 | E18: =Datos!$C$11 -> 0
B19: Fecha: ____ / ____ / ________ | E19: Fecha: ____ / ____ / ________
B22: Formato gratuito de ASEGURA SIG · WhatsApp 302 337 9738 · asegurasig.2026@asegurasig.com
